/home/hslee/anaconda3/lib/python3.11/site-packages/torch/distributed/launch.py:181: FutureWarning: The module torch.distributed.launch is deprecated
and will be removed in future. Use torchrun.
Note that --use-env is set by default in torchrun.
If your script expects `--local-rank` argument to be set, please
change it to read from `os.environ['LOCAL_RANK']` instead. See 
https://pytorch.org/docs/stable/distributed.html#launch-utility for 
further instructions

  warnings.warn(
WARNING:torch.distributed.run:
*****************************************
Setting OMP_NUM_THREADS environment variable for each process to be 1 in default, to avoid your system being overloaded, please further tune the variable for optimal performance in your application as needed. 
*****************************************
<<<<<<< HEAD
| distributed init (rank 1): env://
| distributed init (rank 0): env://
Namespace(data_path='/media/data/coco/images', dataset='coco', model='retinanet_resnet50_fpn', device='cuda', batch_size=8, epochs=26, workers=4, opt='sgd', lr=0.005, momentum=0.9, weight_decay=0.0001, norm_weight_decay=None, lr_scheduler='multisteplr', lr_step_size=8, lr_steps=[16, 22], lr_gamma=0.1, print_freq=20, output_dir='.', resume='', start_epoch=0, aspect_ratio_group_factor=3, rpn_score_thresh=None, trainable_backbone_layers=None, data_augmentation='hflip', sync_bn=False, test_only=False, use_deterministic_algorithms=False, world_size=2, dist_url='env://', weights=None, weights_backbone='ResNet50_Weights.IMAGENET1K_V1', amp=False, use_copypaste=False, backend='pil', use_v2=False, rank=0, gpu=0, distributed=True, dist_backend='nccl')
Loading data
Traceback (most recent call last):
loading annotations into memory...
  File "/home/hslee/Desktop/Backbone-Neck_Self-Distillation/RetinaNet/train.py", line 334, in <module>
Traceback (most recent call last):
  File "/home/hslee/Desktop/Backbone-Neck_Self-Distillation/RetinaNet/train.py", line 334, in <module>
    main(args)
    main(args)
  File "/home/hslee/Desktop/Backbone-Neck_Self-Distillation/RetinaNet/train.py", line 206, in main
  File "/home/hslee/Desktop/Backbone-Neck_Self-Distillation/RetinaNet/train.py", line 206, in main
    dataset, num_classes = get_dataset(is_train=True, args=args)
                           ^^^^^^^^^^^^^^^^^^^^^^^^^^^^^^^^^^^^^
  File "/home/hslee/Desktop/Backbone-Neck_Self-Distillation/RetinaNet/train.py", line 47, in get_dataset
    ds = get_coco(
         ^^^^^^^^^
  File "/home/hslee/Desktop/Backbone-Neck_Self-Distillation/RetinaNet/coco_utils.py", line 227, in get_coco
    dataset = CocoDetection(img_folder, ann_file, transforms=transforms)
              ^^^^^^^^^^^^^^^^^^^^^^^^^^^^^^^^^^^^^^^^^^^^^^^^^^^^^^^^^^
  File "/home/hslee/Desktop/Backbone-Neck_Self-Distillation/RetinaNet/coco_utils.py", line 188, in __init__
        super().__init__(img_folder, ann_file)
dataset, num_classes = get_dataset(is_train=True, args=args)
  File "/home/hslee/anaconda3/lib/python3.11/site-packages/torchvision/datasets/coco.py", line 36, in __init__
    self.coco = COCO(annFile)
                ^^^^^^^^^^^^^
  File "/home/hslee/anaconda3/lib/python3.11/site-packages/pycocotools/coco.py", line 81, in __init__
                 with open(annotation_file, 'r') as f:
                    ^^ ^^^^ ^^^ ^^^^^^^^^^^^^^^^^^^^^^
^^FileNotFoundError^^: [Errno 2] No such file or directory: '/media/data/coco/images/annotations/instances_train2017.json'^
^^^^^^^^^^^^^^^^^^^^^^^^^^^
  File "/home/hslee/Desktop/Backbone-Neck_Self-Distillation/RetinaNet/train.py", line 47, in get_dataset
    ds = get_coco(
         ^^^^^^^^^
  File "/home/hslee/Desktop/Backbone-Neck_Self-Distillation/RetinaNet/coco_utils.py", line 227, in get_coco
    dataset = CocoDetection(img_folder, ann_file, transforms=transforms)
              ^^^^^^^^^^^^^^^^^^^^^^^^^^^^^^^^^^^^^^^^^^^^^^^^^^^^^^^^^^
  File "/home/hslee/Desktop/Backbone-Neck_Self-Distillation/RetinaNet/coco_utils.py", line 188, in __init__
    super().__init__(img_folder, ann_file)
  File "/home/hslee/anaconda3/lib/python3.11/site-packages/torchvision/datasets/coco.py", line 36, in __init__
    self.coco = COCO(annFile)
                ^^^^^^^^^^^^^
  File "/home/hslee/anaconda3/lib/python3.11/site-packages/pycocotools/coco.py", line 81, in __init__
    with open(annotation_file, 'r') as f:
         ^^^^^^^^^^^^^^^^^^^^^^^^^^
FileNotFoundError: [Errno 2] No such file or directory: '/media/data/coco/images/annotations/instances_train2017.json'
ERROR:torch.distributed.elastic.multiprocessing.api:failed (exitcode: 1) local_rank: 0 (pid: 1251977) of binary: /home/hslee/anaconda3/bin/python
=======
Traceback (most recent call last):
  File "/home/hslee/Backbone-Neck-Self-Distillation/RetinaNet/train.py", line 28, in <module>
    import models.detection
  File "/home/hslee/Backbone-Neck-Self-Distillation/RetinaNet/models/__init__.py", line 7, in <module>
    from . import detection
  File "/home/hslee/Backbone-Neck-Self-Distillation/RetinaNet/models/detection/__init__.py", line 1, in <module>
    from ..retinanet import *
  File "/home/hslee/Backbone-Neck-Self-Distillation/RetinaNet/models/retinanet.py", line 728, in <module>
    @register_model()
     ^^^^^^^^^^^^^^^^
  File "/home/hslee/anaconda3/lib/python3.11/site-packages/torchvision/models/_api.py", line 197, in wrapper
    raise ValueError(f"An entry is already registered under the name '{key}'.")
ValueError: An entry is already registered under the name 'retinanet_resnet50_fpn'.
Traceback (most recent call last):
  File "/home/hslee/Backbone-Neck-Self-Distillation/RetinaNet/train.py", line 28, in <module>
    import models.detection
  File "/home/hslee/Backbone-Neck-Self-Distillation/RetinaNet/models/__init__.py", line 7, in <module>
    from . import detection
  File "/home/hslee/Backbone-Neck-Self-Distillation/RetinaNet/models/detection/__init__.py", line 1, in <module>
    from ..retinanet import *
  File "/home/hslee/Backbone-Neck-Self-Distillation/RetinaNet/models/retinanet.py", line 728, in <module>
    @register_model()
     ^^^^^^^^^^^^^^^^
  File "/home/hslee/anaconda3/lib/python3.11/site-packages/torchvision/models/_api.py", line 197, in wrapper
    raise ValueError(f"An entry is already registered under the name '{key}'.")
ValueError: An entry is already registered under the name 'retinanet_resnet50_fpn'.
ERROR:torch.distributed.elastic.multiprocessing.api:failed (exitcode: 1) local_rank: 0 (pid: 899730) of binary: /home/hslee/anaconda3/bin/python
>>>>>>> d4bd215 (cleaning)
Traceback (most recent call last):
  File "<frozen runpy>", line 198, in _run_module_as_main
  File "<frozen runpy>", line 88, in _run_code
  File "/home/hslee/anaconda3/lib/python3.11/site-packages/torch/distributed/launch.py", line 196, in <module>
    main()
  File "/home/hslee/anaconda3/lib/python3.11/site-packages/torch/distributed/launch.py", line 192, in main
    launch(args)
  File "/home/hslee/anaconda3/lib/python3.11/site-packages/torch/distributed/launch.py", line 177, in launch
    run(args)
  File "/home/hslee/anaconda3/lib/python3.11/site-packages/torch/distributed/run.py", line 785, in run
    elastic_launch(
  File "/home/hslee/anaconda3/lib/python3.11/site-packages/torch/distributed/launcher/api.py", line 134, in __call__
    return launch_agent(self._config, self._entrypoint, list(args))
           ^^^^^^^^^^^^^^^^^^^^^^^^^^^^^^^^^^^^^^^^^^^^^^^^^^^^^^^^
  File "/home/hslee/anaconda3/lib/python3.11/site-packages/torch/distributed/launcher/api.py", line 250, in launch_agent
    raise ChildFailedError(
torch.distributed.elastic.multiprocessing.errors.ChildFailedError: 
============================================================
train.py FAILED
------------------------------------------------------------
Failures:
[1]:
<<<<<<< HEAD
  time      : 2024-07-30_11:09:42
  host      : ada
  rank      : 1 (local_rank: 1)
  exitcode  : 1 (pid: 1251978)
=======
  time      : 2024-07-30_11:52:54
  host      : pascal
  rank      : 1 (local_rank: 1)
  exitcode  : 1 (pid: 899731)
>>>>>>> d4bd215 (cleaning)
  error_file: <N/A>
  traceback : To enable traceback see: https://pytorch.org/docs/stable/elastic/errors.html
------------------------------------------------------------
Root Cause (first observed failure):
[0]:
<<<<<<< HEAD
  time      : 2024-07-30_11:09:42
  host      : ada
  rank      : 0 (local_rank: 0)
  exitcode  : 1 (pid: 1251977)
=======
  time      : 2024-07-30_11:52:54
  host      : pascal
  rank      : 0 (local_rank: 0)
  exitcode  : 1 (pid: 899730)
>>>>>>> d4bd215 (cleaning)
  error_file: <N/A>
  traceback : To enable traceback see: https://pytorch.org/docs/stable/elastic/errors.html
============================================================
